Workbook

Sheet Data Pegawai
A1: No | B1: NAMA | C1: Status Aktif | D1: Jenis | E1: JAD | F1: PRODI/BAGIAN | G1: NIP YPT | H1: NIDN | I1: NUPTK | J1: STATUS | K1: GELAR DEPAN | L1: GELAR BELAKANG | M1: PENDIDIKAN | N1: TMT MASUK | O1: TMT Keluar | P1: MASA KERJA DOSEN | Q1: Email | R1: No HP | S1: ALAMAT
A2: 1 | B2: Bambang Agus Sumantri | C2: Aktif | D2: Dosen | E2: =IF(D2="DOSEN",VLOOKUP(B2,Dosen!B:Z,11,FALSE),VLOOKUP(B2,TPA!B:Z,7,FALSE)) -> L | F2: Digital Bisnis | G2: 24800005 | H2: 730088001 | I2: 9162758659130123 | J2: =IF(D2="DOSEN",VLOOKUP(B2,Dosen!B:Z,7,FALSE),VLOOKUP(B2,TPA!B:Z,5,FALSE)) -> PROFESIONAL | K2: Dr.M. | L2: S.IP., M.M. | M2: =IF(D2="DOSEN",VLOOKUP(B2,Dosen!B:ZZ,33,FALSE),VLOOKUP(B2,TPA!B:ZZ,44,FALSE)) -> S3 | N2: 45544 | P2: =IF(O2="",DATEDIF(N2,TODAY(),"y")&" tahun "&DATEDIF(N2,TODAY(),"ym")&" bulan ",DATEDIF(N2,O2,"y")&" tahun "&DATEDIF(N2,O2,"ym")&" bulan ") -> 1 tahun 4 bulan | Q2: bambang.sumantri@mhs.unsoed.ac.id | R2: 85235684085 | S2: Dusun Wonorejo RT/RW 004/002 Desa Semanding Kec. PaguKab. Kediri | T2: =VLOOKUP(B3,Dosen!B:Z,11,FALSE) -> AA
A3: 2 | B3: Darlin Aulia | C3: Aktif | D3: Dosen | E3: =IF(D3="DOSEN",VLOOKUP(B3,Dosen!B:Z,11,FALSE),VLOOKUP(B3,TPA!B:Z,7,FALSE)) -> AA | F3: Digital Bisnis | G3: 22920004 | H3: 309069201 | I3: 2941770671230372 | J3: =IF(D3="DOSEN",VLOOKUP(B3,Dosen!B:Z,7,FALSE),VLOOKUP(B3,TPA!B:Z,5,FALSE)) -> PROFESIONAL | L3: S. E., M.S.Ak. | M3: =IF(D3="DOSEN",VLOOKUP(B3,Dosen!B:ZZ,33,FALSE),VLOOKUP(B3,TPA!B:ZZ,44,FALSE)) -> S2 | N3: 44627 | P3: =IF(O3="",DATEDIF(N3,TODAY(),"y")&" tahun "&DATEDIF(N3,TODAY(),"ym")&" bulan ",DATEDIF(N3,O3,"y")&" tahun "&DATEDIF(N3,O3,"ym")&" bulan ") -> 3 tahun 10 bulan | Q3: darlin.aulia@ittelkom-sby.ac.id | R3: 82122074533 | S3: Jl. Sentot Prawirodhirjo XIV/70, Jember Kidul, Kaliwates, Jember
A4: 3 | B4: Dominggo Bayu Baskara | C4: Aktif | D4: Dosen | E4: =IF(D4="DOSEN",VLOOKUP(B4,Dosen!B:Z,11,FALSE),VLOOKUP(B4,TPA!B:Z,7,FALSE)) -> AA | F4: Digital Bisnis | G4: 19900005 | H4: 722069004 | I4: 6954768669130292 | J4: =IF(D4="DOSEN",VLOOKUP(B4,Dosen!B:Z,7,FALSE),VLOOKUP(B4,TPA!B:Z,5,FALSE)) -> TETAP | K4: Ir. | L4: S.T., M.MT. | M4: =IF(D4="DOSEN",VLOOKUP(B4,Dosen!B:ZZ,33,FALSE),VLOOKUP(B4,TPA!B:ZZ,44,FALSE)) -> S2 | N4: 43101 | P4: =IF(O4="",DATEDIF(N4,TODAY(),"y")&" tahun "&DATEDIF(N4,TODAY(),"ym")&" bulan ",DATEDIF(N4,O4,"y")&" tahun "&DATEDIF(N4,O4,"ym")&" bulan ") -> 8 tahun 0 bulan | Q4: domi@ittelkom-sby.ac.id | R4: 85230001444 | S4: Jl. Palem Selatan II MC/163, Waru, Sidoarjo, Jawa Timur 61256
A5: 4 | B5: Sekar Widyasari Putri | C5: Aktif | D5: Dosen | E5: =IF(D5="DOSEN",VLOOKUP(B5,Dosen!B:Z,11,FALSE),VLOOKUP(B5,TPA!B:Z,7,FALSE)) -> AA | F5: Digital Bisnis | G5: 24930005 | H5: 704029302 | I5: 0536771672230252 | J5: =IF(D5="DOSEN",VLOOKUP(B5,Dosen!B:Z,7,FALSE),VLOOKUP(B5,TPA!B:Z,5,FALSE)) -> TETAP | L5: S.A.B., M.Si. | M5: =IF(D5="DOSEN",VLOOKUP(B5,Dosen!B:ZZ,33,FALSE),VLOOKUP(B5,TPA!B:ZZ,44,FALSE)) -> S2 | N5: 44166 | P5: =IF(O5="",DATEDIF(N5,TODAY(),"y")&" tahun "&DATEDIF(N5,TODAY(),"ym")&" bulan ",DATEDIF(N5,O5,"y")&" tahun "&DATEDIF(N5,O5,"ym")&" bulan ") -> 5 tahun 1 bulan | Q5: sekar@ittelkom-sby.ac.id | R5: 81334448548 | S5: Jl. Plamongan Indah Blok G3 No. 24, Batusari, Mranggen, Demak
A6: 5 | B6: Riza Akhsani Setyo Prayoga | C6: Non-Aktif | D6: Dosen | E6: =IF(D6="DOSEN",VLOOKUP(B6,Dosen!B:Z,11,FALSE),VLOOKUP(B6,TPA!B:Z,7,FALSE)) -> AA | F6: Digital Bisnis | G6: 20940041 | H6: 730049402 | J6: =IF(D6="DOSEN",VLOOKUP(B6,Dosen!B:Z,7,FALSE),VLOOKUP(B6,TPA!B:Z,5,FALSE)) -> PROFESIONAL | L6: S.Kom., M.MT. | M6: =IF(D6="DOSEN",VLOOKUP(B6,Dosen!B:ZZ,33,FALSE),VLOOKUP(B6,TPA!B:ZZ,44,FALSE)) -> S2 | N6: 44166 | O6: 45473 | P6: =IF(O6="",DATEDIF(N6,TODAY(),"y")&" tahun "&DATEDIF(N6,TODAY(),"ym")&" bulan ",DATEDIF(N6,O6,"y")&" tahun "&DATEDIF(N6,O6,"ym")&" bulan ") -> 3 tahun 6 bulan | Q6: rizayoga30@ittelkom-sby.ac.id | R6: 81286153175 | S6: Jl. Ukel GG 1 No. 26, Kertosari, Babadan, Ponorogo
A7: 6 | B7: Caesareano Lafado Yesa | C7: Aktif | D7: Dosen | E7: =IF(D7="DOSEN",VLOOKUP(B7,Dosen!B:Z,11,FALSE),VLOOKUP(B7,TPA!B:Z,7,FALSE)) -> AA | F7: Digital Bisnis | G7: 15890076 | H7: 708128901 | I7: 7540767668130283 | J7: =IF(D7="DOSEN",VLOOKUP(B7,Dosen!B:Z,7,FALSE),VLOOKUP(B7,TPA!B:Z,5,FALSE)) -> TETAP | L7: S.M.B., M.M. | M7: =IF(D7="DOSEN",VLOOKUP(B7,Dosen!B:ZZ,33,FALSE),VLOOKUP(B7,TPA!B:ZZ,44,FALSE)) -> S2 | N7: 44652 | P7: =IF(O7="",DATEDIF(N7,TODAY(),"y")&" tahun "&DATEDIF(N7,TODAY(),"ym")&" bulan ",DATEDIF(N7,O7,"y")&" tahun "&DATEDIF(N7,O7,"ym")&" bulan ") -> 3 tahun 9 bulan | Q7: anofado@ittelkom-sby.ac.id | R7: 81214806006 | S7: Jl. Eka Surya Gg. Eka Dewi No. 2A, Gedung Johor, Medan Johor, Medan
A8: 7 | B8: Titus Kristanto | C8: Aktif | D8: Dosen | E8: =IF(D8="DOSEN",VLOOKUP(B8,Dosen!B:Z,11,FALSE),VLOOKUP(B8,TPA!B:Z,7,FALSE)) -> L | F8: Digital Bisnis | G8: 20860014 | H8: 710028604 | I8: 7542764665137062 | J8: =IF(D8="DOSEN",VLOOKUP(B8,Dosen!B:Z,7,FALSE),VLOOKUP(B8,TPA!B:Z,5,FALSE)) -> TETAP | L8: S.Kom., M.Kom. | M8: =IF(D8="DOSEN",VLOOKUP(B8,Dosen!B:ZZ,33,FALSE),VLOOKUP(B8,TPA!B:ZZ,44,FALSE)) -> S2 | N8: 43282 | P8: =IF(O8="",DATEDIF(N8,TODAY(),"y")&" tahun "&DATEDIF(N8,TODAY(),"ym")&" bulan ",DATEDIF(N8,O8,"y")&" tahun "&DATEDIF(N8,O8,"ym")&" bulan ") -> 7 tahun 6 bulan | Q8: titus.kristanto@ittelkom-sby.ac.id | R8: 81325019978 | S8: Jl. Darmo Indah Selatan 3 Blok GG-25 Surabaya
A9: 8 | B9: Agoes Windarto | C9: Aktif | D9: Dosen | E9: =IF(D9="DOSEN",VLOOKUP(B9,Dosen!B:Z,11,FALSE),VLOOKUP(B9,TPA!B:Z,7,FALSE)) -> AA | F9: Digital Bisnis | G9: 15720039 | H9: 8961580023 | I9: 1138750652130163 | J9: =IF(D9="DOSEN",VLOOKUP(B9,Dosen!B:Z,7,FALSE),VLOOKUP(B9,TPA!B:Z,5,FALSE)) -> PERBANTUAN | L9: S.T., M.M. | M9: =IF(D9="DOSEN",VLOOKUP(B9,Dosen!B:ZZ,33,FALSE),VLOOKUP(B9,TPA!B:ZZ,44,FALSE)) -> S2 | N9: 44562 | P9: =IF(O9="",DATEDIF(N9,TODAY(),"y")&" tahun "&DATEDIF(N9,TODAY(),"ym")&" bulan ",DATEDIF(N9,O9,"y")&" tahun "&DATEDIF(N9,O9,"ym")&" bulan ") -> 4 tahun 0 bulan | Q9: agoeswindarto@ittelkom-sby.ac.id | R9: 81334395366 | S9: Graha Asri Sukodono, Pekarungan, Sidoarjo
A10: 9 | B10: Wachda Yuniar Rochmah | C10: Aktif | D10: Dosen | E10: =IF(D10="DOSEN",VLOOKUP(B10,Dosen!B:Z,11,FALSE),VLOOKUP(B10,TPA!B:Z,7,FALSE)) -> AA | F10: Digital Bisnis | G10: 22970043 | H10: 701069701 | I10: 6933775676230162 | J10: =IF(D10="DOSEN",VLOOKUP(B10,Dosen!B:Z,7,FALSE),VLOOKUP(B10,TPA!B:Z,5,FALSE)) -> PROFESIONAL | L10: S.M., M.M. | M10: =IF(D10="DOSEN",VLOOKUP(B10,Dosen!B:ZZ,33,FALSE),VLOOKUP(B10,TPA!B:ZZ,44,FALSE)) -> S2 | N10: 44832 | P10: =IF(O10="",DATEDIF(N10,TODAY(),"y")&" tahun "&DATEDIF(N10,TODAY(),"ym")&" bulan ",DATEDIF(N10,O10,"y")&" tahun "&DATEDIF(N10,O10,"ym")&" bulan ") -> 3 tahun 3 bulan | Q10: wachdayuniar@ittelkom-sby.ac.id | R10: 82234320272 | S10: Mojoranu, Dander, Bojonegoro
A11: 10 | B11: Adisya Resti Rahmadanti | C11: Non-Aktif | D11: Dosen | E11: =IF(D11="DOSEN",VLOOKUP(B11,Dosen!B:Z,11,FALSE),VLOOKUP(B11,TPA!B:Z,7,FALSE)) -> NJAD | F11: Digital Bisnis | G11: 23990018 | H11: 727019901 | I11: 0459777678230052 | J11: =IF(D11="DOSEN",VLOOKUP(B11,Dosen!B:Z,7,FALSE),VLOOKUP(B11,TPA!B:Z,5,FALSE)) -> PROFESIONAL | L11: S.M., M.A.B. | M11: =IF(D11="DOSEN",VLOOKUP(B11,Dosen!B:ZZ,33,FALSE),VLOOKUP(B11,TPA!B:ZZ,44,FALSE)) -> S2 | N11: 45170 | P11: =IF(O11="",DATEDIF(N11,TODAY(),"y")&" tahun "&DATEDIF(N11,TODAY(),"ym")&" bulan ",DATEDIF(N11,O11,"y")&" tahun "&DATEDIF(N11,O11,"ym")&" bulan ") -> 2 tahun 4 bulan | Q11: adisya@ittelkom-sby.ac.id | R11: 81529137179 | S11: Jl. Gedong Kuning 40A, Jogjakarta, 5517
A12: 11 | B12: Krisnayanti Aditasari | C12: Aktif | D12: Dosen | E12: =IF(D12="DOSEN",VLOOKUP(B12,Dosen!B:Z,11,FALSE),VLOOKUP(B12,TPA!B:Z,7,FALSE)) -> AA | F12: Digital Bisnis | G12: 23990019 | H12: 704069901 | I12: 5936777678230072 | J12: =IF(D12="DOSEN",VLOOKUP(B12,Dosen!B:Z,7,FALSE),VLOOKUP(B12,TPA!B:Z,5,FALSE)) -> PROFESIONAL | L12: S.M., M.MT. | M12: =IF(D12="DOSEN",VLOOKUP(B12,Dosen!B:ZZ,33,FALSE),VLOOKUP(B12,TPA!B:ZZ,44,FALSE)) -> S2 | N12: 45170 | P12: =IF(O12="",DATEDIF(N12,TODAY(),"y")&" tahun "&DATEDIF(N12,TODAY(),"ym")&" bulan ",DATEDIF(N12,O12,"y")&" tahun "&DATEDIF(N12,O12,"ym")&" bulan ") -> 2 tahun 4 bulan | Q12: krisna@ittelkom-sby.ac.id | R12: 81223566959 | S12: Tambak Medokan Ayu XVI / 4, Surabaya, 60295
A13: 12 | B13: Rudi Harianto | C13: Non-Aktif | D13: Dosen | E13: =IF(D13="DOSEN",VLOOKUP(B13,Dosen!B:Z,11,FALSE),VLOOKUP(B13,TPA!B:Z,7,FALSE)) -> AA | F13: Digital Bisnis | G13: 24870001 | H13: 701108702 | J13: =IF(D13="DOSEN",VLOOKUP(B13,Dosen!B:Z,7,FALSE),VLOOKUP(B13,TPA!B:Z,5,FALSE)) -> PROFESIONAL | L13: S.E., M.A. | M13: =IF(D13="DOSEN",VLOOKUP(B13,Dosen!B:ZZ,33,FALSE),VLOOKUP(B13,TPA!B:ZZ,44,FALSE)) -> S2 | N13: 45505 | O13: 45688 | P13: =IF(O13="",DATEDIF(N13,TODAY(),"y")&" tahun "&DATEDIF(N13,TODAY(),"ym")&" bulan ",DATEDIF(N13,O13,"y")&" tahun "&DATEDIF(N13,O13,"ym")&" bulan ") -> 0 tahun 5 bulan | R13: 82123556785 | S13: Sidokapasan 1/54 SBY RT 001 RW 001, Kel. Sidodadi, Kec. Simokerto, Kota Surabaya, Jawa Timur
A14: 13 | B14: N. Azizia Gia Mutiarasari | C14: Aktif | D14: Dosen | E14: =IF(D14="DOSEN",VLOOKUP(B14,Dosen!B:Z,11,FALSE),VLOOKUP(B14,TPA!B:Z,7,FALSE)) -> NJAD | F14: Digital Bisnis | G14: 24970010 | H14: 5149775676230303 | I14: 5149775676230303 | J14: =IF(D14="DOSEN",VLOOKUP(B14,Dosen!B:Z,7,FALSE),VLOOKUP(B14,TPA!B:Z,5,FALSE)) -> PROFESIONAL | L14: S.M., MBA | M14: =IF(D14="DOSEN",VLOOKUP(B14,Dosen!B:ZZ,33,FALSE),VLOOKUP(B14,TPA!B:ZZ,44,FALSE)) -> S3 | N14: 45536 | P14: =IF(O14="",DATEDIF(N14,TODAY(),"y")&" tahun "&DATEDIF(N14,TODAY(),"ym")&" bulan ",DATEDIF(N14,O14,"y")&" tahun "&DATEDIF(N14,O14,"ym")&" bulan ") -> 1 tahun 4 bulan | Q14: giamsari17@gmail.com | R14: 82134623762 | S14: Rejosari RT 003 RT 008, Kel. Sabrang, Kec. Delanggu, Kab. Klaten
A15: 14 | B15: Annisa Ramadhan | C15: Aktif | D15: Dosen | E15: =IF(D15="DOSEN",VLOOKUP(B15,Dosen!B:Z,11,FALSE),VLOOKUP(B15,TPA!B:Z,7,FALSE)) -> NJAD | F15: Digital Bisnis | G15: 25950003 | I15: 7545773674230262 | J15: =IF(D15="DOSEN",VLOOKUP(B15,Dosen!B:Z,7,FALSE),VLOOKUP(B15,TPA!B:Z,5,FALSE)) -> PROFESIONAL | L15: S.Stat. M.Stat. | M15: =IF(D15="DOSEN",VLOOKUP(B15,Dosen!B:ZZ,33,FALSE),VLOOKUP(B15,TPA!B:ZZ,44,FALSE)) -> S2 | N15: 45689 | P15: =IF(O15="",DATEDIF(N15,TODAY(),"y")&" tahun "&DATEDIF(N15,TODAY(),"ym")&" bulan ",DATEDIF(N15,O15,"y")&" tahun "&DATEDIF(N15,O15,"ym")&" bulan ") -> 0 tahun 11 bulan | Q15: annisaramadhan807@gmail.com | R15: 81233838309 | S15: JAMBANGAN KEBON AGUNG KEL JAMBANGAN KEC JAMBANGAN SURABAYA
A16: 15 | B16: Egi Gumala Sari | C16: Non-Aktif | D16: Dosen | E16: =IF(D16="DOSEN",VLOOKUP(B16,Dosen!B:Z,11,FALSE),VLOOKUP(B16,TPA!B:Z,7,FALSE)) -> NJAD | F16: Digital Bisnis | G16: 25980005 | J16: =IF(D16="DOSEN",VLOOKUP(B16,Dosen!B:Z,7,FALSE),VLOOKUP(B16,TPA!B:Z,5,FALSE)) -> PROFESIONAL | L16: S.E., M.Ak. | M16: =IF(D16="DOSEN",VLOOKUP(B16,Dosen!B:ZZ,33,FALSE),VLOOKUP(B16,TPA!B:ZZ,44,FALSE)) -> S2 | N16: 45689 | O16: 45869 | P16: =IF(O16="",DATEDIF(N16,TODAY(),"y")&" tahun "&DATEDIF(N16,TODAY(),"ym")&" bulan ",DATEDIF(N16,O16,"y")&" tahun "&DATEDIF(N16,O16,"ym")&" bulan ") -> 0 tahun 5 bulan | Q16: riset.egigumalasari@gmail.com | R16: 82123510747 | S16: jl perintis kemardekaan no 154 kel padang matinggi
A17: 16 | B17: Wahyu Eka Kiswardani | C17: Aktif | D17: Dosen | E17: =IF(D17="DOSEN",VLOOKUP(B17,Dosen!B:Z,11,FALSE),VLOOKUP(B17,TPA!B:Z,7,FALSE)) -> NJAD | F17: Digital Bisnis | G17: 25010008 | H17: 0452779680230052 | I17: 0452779680230052 | J17: =IF(D17="DOSEN",VLOOKUP(B17,Dosen!B:Z,7,FALSE),VLOOKUP(B17,TPA!B:Z,5,FALSE)) -> PROFESIONAL | L17: S.M., M.M. | M17: =IF(D17="DOSEN",VLOOKUP(B17,Dosen!B:ZZ,33,FALSE),VLOOKUP(B17,TPA!B:ZZ,44,FALSE)) -> S2 | N17: 45689 | P17: =IF(O17="",DATEDIF(N17,TODAY(),"y")&" tahun "&DATEDIF(N17,TODAY(),"ym")&" bulan ",DATEDIF(N17,O17,"y")&" tahun "&DATEDIF(N17,O17,"ym")&" bulan ") -> 0 tahun 11 bulan | Q17: wahyuuekafb658@gmail.com | R17: 81222871863 | S17: DESA NGETOS RT 002 RW 002 KEL NGETOS KEC NGETOS NGANJUK
A18: 17 | B18: Hussein Gibreel Musa Salih | C18: Aktif | D18: Dosen | E18: =IF(D18="DOSEN",VLOOKUP(B18,Dosen!B:Z,11,FALSE),VLOOKUP(B18,TPA!B:Z,7,FALSE)) -> NJAD | F18: Digital Bisnis | G18: 25900003 | J18: =IF(D18="DOSEN",VLOOKUP(B18,Dosen!B:Z,7,FALSE),VLOOKUP(B18,TPA!B:Z,5,FALSE)) -> PROFESIONAL | L18: B.Art., M.I.kom., Ph.D. | M18: =IF(D18="DOSEN",VLOOKUP(B18,Dosen!B:ZZ,33,FALSE),VLOOKUP(B18,TPA!B:ZZ,44,FALSE)) -> S3 | N18: 45658 | P18: =IF(O18="",DATEDIF(N18,TODAY(),"y")&" tahun "&DATEDIF(N18,TODAY(),"ym")&" bulan ",DATEDIF(N18,O18,"y")&" tahun "&DATEDIF(N18,O18,"ym")&" bulan ") -> 1 tahun 0 bulan | Q18: husseingibreelmusa@gmail.com | S18: Anugrah Batako RT 006 RW 000, Kel. Argorejo, Kec. Sedayu, Kab. Bantul
A19: 18 | B19: Ardian Yusuf Wicaksono | C19: Aktif | D19: Dosen | E19: =IF(D19="DOSEN",VLOOKUP(B19,Dosen!B:Z,11,FALSE),VLOOKUP(B19,TPA!B:Z,7,FALSE)) -> AA | F19: Informatika | G19: 18920109 | H19: 727099201 | I19: 5259770671130293 | J19: =IF(D19="DOSEN",VLOOKUP(B19,Dosen!B:Z,7,FALSE),VLOOKUP(B19,TPA!B:Z,5,FALSE)) -> TETAP | L19: S.Kom., M.Kom. | M19: =IF(D19="DOSEN",VLOOKUP(B19,Dosen!B:ZZ,33,FALSE),VLOOKUP(B19,TPA!B:ZZ,44,FALSE)) -> S2 | N19: 43282 | P19: =IF(O19="",DATEDIF(N19,TODAY(),"y")&" tahun "&DATEDIF(N19,TODAY(),"ym")&" bulan ",DATEDIF(N19,O19,"y")&" tahun "&DATEDIF(N19,O19,"ym")&" bulan ") -> 7 tahun 6 bulan | Q19: ardian@ittelkom-sby.ac.id | R19: 82245510526 | S19: Jalan Mayor Bismo No. 26A RT/RW 02/02, Templek, Gadungan, Puncu, Kediri
A20: 19 | B20: Ahmad Wali Satria Bahari Johan | C20: Aktif | D20: Dosen | E20: =IF(D20="DOSEN",VLOOKUP(B20,Dosen!B:Z,11,FALSE),VLOOKUP(B20,TPA!B:Z,7,FALSE)) -> L | F20: Informatika | G20: 20950043 | H20: 713059501 | I20: 7845773674130212 | J20: =IF(D20="DOSEN",VLOOKUP(B20,Dosen!B:Z,7,FALSE),VLOOKUP(B20,TPA!B:Z,5,FALSE)) -> TETAP | L20: S.ST., M.Kom. | M20: =IF(D20="DOSEN",VLOOKUP(B20,Dosen!B:ZZ,33,FALSE),VLOOKUP(B20,TPA!B:ZZ,44,FALSE)) -> S2 | N20: 44166 | P20: =IF(O20="",DATEDIF(N20,TODAY(),"y")&" tahun "&DATEDIF(N20,TODAY(),"ym")&" bulan ",DATEDIF(N20,O20,"y")&" tahun "&DATEDIF(N20,O20,"ym")&" bulan ") -> 5 tahun 1 bulan | Q20: ahmadsatria13@ittelkom-sby.ac.id | R20: 82132194465 | S20: Dsn. Bujel, Suwaloh, Balen, Bojonegoro
A21: 20 | B21: Muhammad Dzulfikar Fauzi | C21: Aktif | D21: Dosen | E21: =IF(D21="DOSEN",VLOOKUP(B21,Dosen!B:Z,11,FALSE),VLOOKUP(B21,TPA!B:Z,7,FALSE)) -> L | F21: Informatika | G21: 20940043 | H21: 711039403 | I21: 2643772673130292 | J21: =IF(D21="DOSEN",VLOOKUP(B21,Dosen!B:Z,7,FALSE),VLOOKUP(B21,TPA!B:Z,5,FALSE)) -> TETAP | L21: S.Kom., M.Cs. | M21: =IF(D21="DOSEN",VLOOKUP(B21,Dosen!B:ZZ,33,FALSE),VLOOKUP(B21,TPA!B:ZZ,44,FALSE)) -> S2 | N21: 44166 | P21: =IF(O21="",DATEDIF(N21,TODAY(),"y")&" tahun "&DATEDIF(N21,TODAY(),"ym")&" bulan ",DATEDIF(N21,O21,"y")&" tahun "&DATEDIF(N21,O21,"ym")&" bulan ") -> 5 tahun 1 bulan | Q21: muhammad.dzulfikar.f@ittelkom-sby.ac.id | R21: 85323076783 | S21: Dsn. Kayen, Morosunggingan, Peterongan, Jombang
A22: 21 | B22: Kharisma Monika Dian Pertiwi | C22: Aktif | D22: Dosen | E22: =IF(D22="DOSEN",VLOOKUP(B22,Dosen!B:Z,11,FALSE),VLOOKUP(B22,TPA!B:Z,7,FALSE)) -> AA | F22: Informatika | G22: 23950024 | H22: 706089501 | I22: 4138773674230223 | J22: =IF(D22="DOSEN",VLOOKUP(B22,Dosen!B:Z,7,FALSE),VLOOKUP(B22,TPA!B:Z,5,FALSE)) -> TETAP | L22: S.Kom., M.Kom. | M22: =IF(D22="DOSEN",VLOOKUP(B22,Dosen!B:ZZ,33,FALSE),VLOOKUP(B22,TPA!B:ZZ,44,FALSE)) -> S2 | N22: 44166 | P22: =IF(O22="",DATEDIF(N22,TODAY(),"y")&" tahun "&DATEDIF(N22,TODAY(),"ym")&" bulan ",DATEDIF(N22,O22,"y")&" tahun "&DATEDIF(N22,O22,"ym")&" bulan ") -> 5 tahun 1 bulan | Q22: kharismamonika@ittelkom-sby.ac.id | R22: 81233777404 | S22: Jl. YKP Pandugo 2F-4, Penjaringan Sari, Rungkut, Surabaya
A23: 22 | B23: Rizky Fenaldo Maulana | C23: Aktif | D23: Dosen | E23: =IF(D23="DOSEN",VLOOKUP(B23,Dosen!B:Z,11,FALSE),VLOOKUP(B23,TPA!B:Z,7,FALSE)) -> AA | F23: Informatika | G23: 20970031 | H23: 714079701 | I23: 2046775676130173 | J23: =IF(D23="DOSEN",VLOOKUP(B23,Dosen!B:Z,7,FALSE),VLOOKUP(B23,TPA!B:Z,5,FALSE)) -> TETAP | L23: S.Kom., M.Kom. | M23: =IF(D23="DOSEN",VLOOKUP(B23,Dosen!B:ZZ,33,FALSE),VLOOKUP(B23,TPA!B:ZZ,44,FALSE)) -> S2 | N23: 44166 | P23: =IF(O23="",DATEDIF(N23,TODAY(),"y")&" tahun "&DATEDIF(N23,TODAY(),"ym")&" bulan ",DATEDIF(N23,O23,"y")&" tahun "&DATEDIF(N23,O23,"ym")&" bulan ") -> 5 tahun 1 bulan | Q23: aldo@ittelkom-sby.ac.id | R23: 81230777099 | S23: Jl. Gajayana No. 796, Dinoyo, Lowokwaru, Malang
A24: 23 | B24: Vessa Rizky Oktavia | C24: Aktif | D24: Dosen | E24: =IF(D24="DOSEN",VLOOKUP(B24,Dosen!B:Z,11,FALSE),VLOOKUP(B24,TPA!B:Z,7,FALSE)) -> AA | F24: Informatika | G24: 22950051 | H24: 705109501 | I24: 7337773674230273 | J24: =IF(D24="DOSEN",VLOOKUP(B24,Dosen!B:Z,7,FALSE),VLOOKUP(B24,TPA!B:Z,5,FALSE)) -> PROFESIONAL | L24: S.Kom., M.Kom. | M24: =IF(D24="DOSEN",VLOOKUP(B24,Dosen!B:ZZ,33,FALSE),VLOOKUP(B24,TPA!B:ZZ,44,FALSE)) -> S2 | N24: 44832 | P24: =IF(O24="",DATEDIF(N24,TODAY(),"y")&" tahun "&DATEDIF(N24,TODAY(),"ym")&" bulan ",DATEDIF(N24,O24,"y")&" tahun "&DATEDIF(N24,O24,"ym")&" bulan ") -> 3 tahun 3 bulan | Q24: vessa@ittelkom-sby.ac.id | R24: 82139322002 | S24: Alun Alun Rangkah NO 17-II, Tambaksari, Surabaya
A25: 24 | B25: Alqis Rausanfita | C25: Aktif | D25: Dosen | E25: =IF(D25="DOSEN",VLOOKUP(B25,Dosen!B:Z,11,FALSE),VLOOKUP(B25,TPA!B:Z,7,FALSE)) -> AA | F25: Informatika | G25: 22960060 | H25: 710029601 | I25: 7542774675230212 | J25: =IF(D25="DOSEN",VLOOKUP(B25,Dosen!B:Z,7,FALSE),VLOOKUP(B25,TPA!B:Z,5,FALSE)) -> PROFESIONAL | L25: S.Kom., M.Kom. | M25: =IF(D25="DOSEN",VLOOKUP(B25,Dosen!B:ZZ,33,FALSE),VLOOKUP(B25,TPA!B:ZZ,44,FALSE)) -> S2 | N25: 44832 | P25: =IF(O25="",DATEDIF(N25,TODAY(),"y")&" tahun "&DATEDIF(N25,TODAY(),"ym")&" bulan ",DATEDIF(N25,O25,"y")&" tahun "&DATEDIF(N25,O25,"ym")&" bulan ") -> 3 tahun 3 bulan | Q25: alqisrausanfita@ittelkom-sby.ac.id | R25: 82143463645 | S25: Ngagel Mulya 8/42, Wonokromo, Surabaya
A26: 25 | B26: Daud Muhajir | C26: Aktif | D26: Dosen | E26: =IF(D26="DOSEN",VLOOKUP(B26,Dosen!B:Z,11,FALSE),VLOOKUP(B26,TPA!B:Z,7,FALSE)) -> AA | F26: Informatika | G26: 23970024 | H26: 711079701 | I26: 5043775676130143 | J26: =IF(D26="DOSEN",VLOOKUP(B26,Dosen!B:Z,7,FALSE),VLOOKUP(B26,TPA!B:Z,5,FALSE)) -> PROFESIONAL | L26: S.Kom., M.Kom. | M26: =IF(D26="DOSEN",VLOOKUP(B26,Dosen!B:ZZ,33,FALSE),VLOOKUP(B26,TPA!B:ZZ,44,FALSE)) -> S2 | N26: 45170 | P26: =IF(O26="",DATEDIF(N26,TODAY(),"y")&" tahun "&DATEDIF(N26,TODAY(),"ym")&" bulan ",DATEDIF(N26,O26,"y")&" tahun "&DATEDIF(N26,O26,"ym")&" bulan ") -> 2 tahun 4 bulan | Q26: daud@ittelkom-sby.ac.id | R26: 81227926332 | S26: Klakahrejo Lor Gg. Arwana 34, Surabaya
A27: 26 | B27: Dyah Putri Rahmawati | C27: Aktif | D27: Dosen | E27: =IF(D27="DOSEN",VLOOKUP(B27,Dosen!B:Z,11,FALSE),VLOOKUP(B27,TPA!B:Z,7,FALSE)) -> L | F27: Informatika | G27: 23960023 | H27: 719039601 | I27: 3651774675230192 | J27: =IF(D27="DOSEN",VLOOKUP(B27,Dosen!B:Z,7,FALSE),VLOOKUP(B27,TPA!B:Z,5,FALSE)) -> PROFESIONAL | K27: Dr. | L27: S.Stat. | M27: =IF(D27="DOSEN",VLOOKUP(B27,Dosen!B:ZZ,33,FALSE),VLOOKUP(B27,TPA!B:ZZ,44,FALSE)) -> S3 | N27: 45170 | P27: =IF(O27="",DATEDIF(N27,TODAY(),"y")&" tahun "&DATEDIF(N27,TODAY(),"ym")&" bulan ",DATEDIF(N27,O27,"y")&" tahun "&DATEDIF(N27,O27,"ym")&" bulan ") -> 2 tahun 4 bulan | Q27: dyahputri@ittelkom-sby.ac.id | R27: 82131803152 | S27: Jl. Turkis V-15, Sooko, Mojokerto, 61361
A28: 27 | B28: Pima Hani Safitri | C28: Aktif | D28: Dosen | E28: =IF(D28="DOSEN",VLOOKUP(B28,Dosen!B:Z,11,FALSE),VLOOKUP(B28,TPA!B:Z,7,FALSE)) -> NJAD | F28: Informatika | G28: 23950016 | H28: 703039502 | I28: 2635773674230322 | J28: =IF(D28="DOSEN",VLOOKUP(B28,Dosen!B:Z,7,FALSE),VLOOKUP(B28,TPA!B:Z,5,FALSE)) -> PROFESIONAL | L28: S.Kom., M.Kom. | M28: =IF(D28="DOSEN",VLOOKUP(B28,Dosen!B:ZZ,33,FALSE),VLOOKUP(B28,TPA!B:ZZ,44,FALSE)) -> S2 | N28: 45170 | P28: =IF(O28="",DATEDIF(N28,TODAY(),"y")&" tahun "&DATEDIF(N28,TODAY(),"ym")&" bulan ",DATEDIF(N28,O28,"y")&" tahun "&DATEDIF(N28,O28,"ym")&" bulan ") -> 2 tahun 4 bulan | Q28: pimahanisafitri@ittelkom-sby.ac.id | R28: 85236699663 | S28: Jl. Jagalan II, Kedok, Turen, Malang, 65175
A29: 28 | B29: Tanzilal Mustaqim | C29: Aktif | D29: Dosen | E29: =IF(D29="DOSEN",VLOOKUP(B29,Dosen!B:Z,11,FALSE),VLOOKUP(B29,TPA!B:Z,7,FALSE)) -> NJAD | F29: Informatika | G29: 23980024 | H29: 714089801 | I29: 3146776677130103 | J29: =IF(D29="DOSEN",VLOOKUP(B29,Dosen!B:Z,7,FALSE),VLOOKUP(B29,TPA!B:Z,5,FALSE)) -> PROFESIONAL | L29: S.Kom., M.Kom. | M29: =IF(D29="DOSEN",VLOOKUP(B29,Dosen!B:ZZ,33,FALSE),VLOOKUP(B29,TPA!B:ZZ,44,FALSE)) -> S3 | N29: 45170 | P29: =IF(O29="",DATEDIF(N29,TODAY(),"y")&" tahun "&DATEDIF(N29,TODAY(),"ym")&" bulan ",DATEDIF(N29,O29,"y")&" tahun "&DATEDIF(N29,O29,"ym")&" bulan ") -> 2 tahun 4 bulan | Q29: tanzilal@ittelkom-sby.ac.id | R29: 85171711408 | S29: Tlogojati, Plosorejo, Gondang, Sragen, 57254
A30: 29 | B30: Fandisya Rahman | C30: Aktif | D30: Dosen | E30: =IF(D30="DOSEN",VLOOKUP(B30,Dosen!B:Z,11,FALSE),VLOOKUP(B30,TPA!B:Z,7,FALSE)) -> NJAD | F30: Informatika | G30: 23900006 | H30: 0711059005 | I30: 2843768669130322 | J30: =IF(D30="DOSEN",VLOOKUP(B30,Dosen!B:Z,7,FALSE),VLOOKUP(B30,TPA!B:Z,5,FALSE)) -> PROFESIONAL | L30: S.Kom., M.Kom. | M30: =IF(D30="DOSEN",VLOOKUP(B30,Dosen!B:ZZ,33,FALSE),VLOOKUP(B30,TPA!B:ZZ,44,FALSE)) -> S2 | N30: 45170 | P30: =IF(O30="",DATEDIF(N30,TODAY(),"y")&" tahun "&DATEDIF(N30,TODAY(),"ym")&" bulan ",DATEDIF(N30,O30,"y")&" tahun "&DATEDIF(N30,O30,"ym")&" bulan ") -> 2 tahun 4 bulan | Q30: rahman@ittelkom-sby.ac.id | R30: 85175442445 | S30: Jl. MT. Haryono XVII / 211, Malang, 65145
A31: 30 | B31: Dimas Chaerul Ekty Saputra | C31: Aktif | D31: Dosen | E31: =IF(D31="DOSEN",VLOOKUP(B31,Dosen!B:Z,11,FALSE),VLOOKUP(B31,TPA!B:Z,7,FALSE)) -> NJAD | F31: Informatika | G31: 24980018 | H31: 6961776677130132 | I31: 6961776677130132 | J31: =IF(D31="DOSEN",VLOOKUP(B31,Dosen!B:Z,7,FALSE),VLOOKUP(B31,TPA!B:Z,5,FALSE)) -> PROFESIONAL | L31: S.Kom., M.Sc. | M31: =IF(D31="DOSEN",VLOOKUP(B31,Dosen!B:ZZ,33,FALSE),VLOOKUP(B31,TPA!B:ZZ,44,FALSE)) -> S3 | N31: 45536 | P31: =IF(O31="",DATEDIF(N31,TODAY(),"y")&" tahun "&DATEDIF(N31,TODAY(),"ym")&" bulan ",DATEDIF(N31,O31,"y")&" tahun "&DATEDIF(N31,O31,"ym")&" bulan ") -> 1 tahun 4 bulan | Q31: dimaschaerul3@gmail.com | R31: 81225763073 | S31: Asrama Polri Pathuk Ng I/598 Rt 030 Rw 006, Kel. Ngampilan, Kec. Ngampilan, Yogyakarta
A32: 31 | B32: Yasinta Romadhona | C32: Aktif | D32: Dosen | E32: =IF(D32="DOSEN",VLOOKUP(B32,Dosen!B:Z,11,FALSE),VLOOKUP(B32,TPA!B:Z,7,FALSE)) -> NJAD | F32: Informatika | G32: 25989002 | I32: 1438776677230172 | J32: =IF(D32="DOSEN",VLOOKUP(B32,Dosen!B:Z,7,FALSE),VLOOKUP(B32,TPA!B:Z,5,FALSE)) -> PROFESIONAL | L32: S.Kom., M.Kom. | M32: =IF(D32="DOSEN",VLOOKUP(B32,Dosen!B:ZZ,33,FALSE),VLOOKUP(B32,TPA!B:ZZ,44,FALSE)) -> S2 | N32: 45717 | P32: =IF(O32="",DATEDIF(N32,TODAY(),"y")&" tahun "&DATEDIF(N32,TODAY(),"ym")&" bulan ",DATEDIF(N32,O32,"y")&" tahun "&DATEDIF(N32,O32,"ym")&" bulan ") -> 0 tahun 10 bulan | Q32: yasinta.rmd@gmail.com | R32: 82225333154 | S32: Dusun Sukobanteng RT 016 RW 004 Desa Karangsoko, Kecamatan Trenggalek, Kabupaten Trenggalek, Jawa Timur
A33: 32 | B33: Billy Montolalu | C33: Aktif | D33: Dosen | E33: =IF(D33="DOSEN",VLOOKUP(B33,Dosen!B:Z,11,FALSE),VLOOKUP(B33,TPA!B:Z,7,FALSE)) -> AA | F33: Rekayasa Perangkat Lunak | G33: 20870004 | H33: 729088704 | I33: 9160765666137003 | J33: =IF(D33="DOSEN",VLOOKUP(B33,Dosen!B:Z,7,FALSE),VLOOKUP(B33,TPA!B:Z,5,FALSE)) -> TETAP | L33: S.Kom., M.Kom. | M33: =IF(D33="DOSEN",VLOOKUP(B33,Dosen!B:ZZ,33,FALSE),VLOOKUP(B33,TPA!B:ZZ,44,FALSE)) -> S2 | N33: 43282 | P33: =IF(O33="",DATEDIF(N33,TODAY(),"y")&" tahun "&DATEDIF(N33,TODAY(),"ym")&" bulan ",DATEDIF(N33,O33,"y")&" tahun "&DATEDIF(N33,O33,"ym")&" bulan ") -> 7 tahun 6 bulan | Q33: billy@ittelkom-sby.ac.id | R33: 85233310837 | S33: DSN. KRAJAN RT 19 RW 5, YOSOWILANGUN LOR, LUMAJANG
A34: 33 | B34: Dahliar Ananda | C34: Aktif | D34: Dosen | E34: =IF(D34="DOSEN",VLOOKUP(B34,Dosen!B:Z,11,FALSE),VLOOKUP(B34,TPA!B:Z,7,FALSE)) -> L | F34: Rekayasa Perangkat Lunak | G34: 9820030 | H34: 402058203 | I34: 9834760661131142 | J34: =IF(D34="DOSEN",VLOOKUP(B34,Dosen!B:Z,7,FALSE),VLOOKUP(B34,TPA!B:Z,5,FALSE)) -> TETAP | L34: S.T., M.T. | M34: =IF(D34="DOSEN",VLOOKUP(B34,Dosen!B:ZZ,33,FALSE),VLOOKUP(B34,TPA!B:ZZ,44,FALSE)) -> S2 | N34: 39845 | P34: =IF(O34="",DATEDIF(N34,TODAY(),"y")&" tahun "&DATEDIF(N34,TODAY(),"ym")&" bulan ",DATEDIF(N34,O34,"y")&" tahun "&DATEDIF(N34,O34,"ym")&" bulan ") -> 16 tahun 11 bulan | Q34: dahliar@ittelkom-sby.ac.id | R34: 8121446627 | S34: Perum Batu Indah Regency Blok C7 no 1, Cilame, Ngamprah, Bandung Barat
A35: 34 | B35: Fidi Wincoko Putro | C35: Aktif | D35: Dosen | E35: =IF(D35="DOSEN",VLOOKUP(B35,Dosen!B:Z,11,FALSE),VLOOKUP(B35,TPA!B:Z,7,FALSE)) -> L | F35: Rekayasa Perangkat Lunak | G35: 19870004 | H35: 730058702 | I35: 1862765666130262 | J35: =IF(D35="DOSEN",VLOOKUP(B35,Dosen!B:Z,7,FALSE),VLOOKUP(B35,TPA!B:Z,5,FALSE)) -> TETAP | L35: S.ST., M.Kom. | M35: =IF(D35="DOSEN",VLOOKUP(B35,Dosen!B:ZZ,33,FALSE),VLOOKUP(B35,TPA!B:ZZ,44,FALSE)) -> S2 | N35: 43101 | P35: =IF(O35="",DATEDIF(N35,TODAY(),"y")&" tahun "&DATEDIF(N35,TODAY(),"ym")&" bulan ",DATEDIF(N35,O35,"y")&" tahun "&DATEDIF(N35,O35,"ym")&" bulan ") -> 8 tahun 0 bulan | Q35: fidiwputro@ittelkom-sby.ac.id | R35: 82143161793 | S35: Jl. Cempaka 42, Kel Bangunsari, Kec Mejayan, Kab Madiun, Jawa Timur
A36: 35 | B36: Mohammad Sholik | C36: Aktif | D36: Dosen | E36: =IF(D36="DOSEN",VLOOKUP(B36,Dosen!B:Z,11,FALSE),VLOOKUP(B36,TPA!B:Z,7,FALSE)) -> AA | F36: Rekayasa Perangkat Lunak | G36: 19810001 | H36: 709128101 | I36: 0541759660130163 | J36: =IF(D36="DOSEN",VLOOKUP(B36,Dosen!B:Z,7,FALSE),VLOOKUP(B36,TPA!B:Z,5,FALSE)) -> TETAP | L36: S.Kom., M.Kom. | M36: =IF(D36="DOSEN",VLOOKUP(B36,Dosen!B:ZZ,33,FALSE),VLOOKUP(B36,TPA!B:ZZ,44,FALSE)) -> S2 | N36: 43101 | P36: =IF(O36="",DATEDIF(N36,TODAY(),"y")&" tahun "&DATEDIF(N36,TODAY(),"ym")&" bulan ",DATEDIF(N36,O36,"y")&" tahun "&DATEDIF(N36,O36,"ym")&" bulan ") -> 8 tahun 0 bulan | Q36: mohammad.sholik@ittelkom-sby.ac.id | R36: 811324984 | S36: LOWAYU, RT. 029 RW. 008, DUKUN, GRESIK 61155
A37: 36 | B37: Dewi Rahmawati | C37: Aktif | D37: Dosen | E37: =IF(D37="DOSEN",VLOOKUP(B37,Dosen!B:Z,11,FALSE),VLOOKUP(B37,TPA!B:Z,7,FALSE)) -> L | F37: Rekayasa Perangkat Lunak | G37: 20940001 | H37: 709039401 | I37: 5641772673230262 | J37: =IF(D37="DOSEN",VLOOKUP(B37,Dosen!B:Z,7,FALSE),VLOOKUP(B37,TPA!B:Z,5,FALSE)) -> TETAP | K37: Dr. | L37: S.Kom., M.Kom. | M37: =IF(D37="DOSEN",VLOOKUP(B37,Dosen!B:ZZ,33,FALSE),VLOOKUP(B37,TPA!B:ZZ,44,FALSE)) -> S3 | N37: 43282 | P37: =IF(O37="",DATEDIF(N37,TODAY(),"y")&" tahun "&DATEDIF(N37,TODAY(),"ym")&" bulan ",DATEDIF(N37,O37,"y")&" tahun "&DATEDIF(N37,O37,"ym")&" bulan ") -> 7 tahun 6 bulan | Q37: dewirahmawati@ittelkom-sby.ac.id | R37: 81359057346 | S37: Perumahan Gempol Citra Asri O-24 Pasuruan
A38: 37 | B38: Achmad Muzakki | C38: Aktif | D38: Dosen | E38: =IF(D38="DOSEN",VLOOKUP(B38,Dosen!B:Z,11,FALSE),VLOOKUP(B38,TPA!B:Z,7,FALSE)) -> L | F38: Rekayasa Perangkat Lunak | G38: 23850011 | H38: 728058503 | I38: 7860763664130242 | J38: =IF(D38="DOSEN",VLOOKUP(B38,Dosen!B:Z,7,FALSE),VLOOKUP(B38,TPA!B:Z,5,FALSE)) -> TETAP | L38: S.Kom., M.Kom. | M38: =IF(D38="DOSEN",VLOOKUP(B38,Dosen!B:ZZ,33,FALSE),VLOOKUP(B38,TPA!B:ZZ,44,FALSE)) -> S2 | N38: 44627 | P38: =IF(O38="",DATEDIF(N38,TODAY(),"y")&" tahun "&DATEDIF(N38,TODAY(),"ym")&" bulan ",DATEDIF(N38,O38,"y")&" tahun "&DATEDIF(N38,O38,"ym")&" bulan ") -> 3 tahun 10 bulan | Q38: achmad.muzakki@ittelkom-sby.ac.id | R38: 81216473232 | S38: Gebang Wetan 1/9, Gebang Putih, Sukolilo, Surabaya
A39: 38 | B39: Arni Muarifah Amri | C39: Aktif | D39: Dosen | E39: =IF(D39="DOSEN",VLOOKUP(B39,Dosen!B:Z,11,FALSE),VLOOKUP(B39,TPA!B:Z,7,FALSE)) -> AA | F39: Rekayasa Perangkat Lunak | G39: 23900007 | H39: 718069004 | I39: 6950768669230322 | J39: =IF(D39="DOSEN",VLOOKUP(B39,Dosen!B:Z,7,FALSE),VLOOKUP(B39,TPA!B:Z,5,FALSE)) -> PROFESIONAL | L39: S.T., M.T. | M39: =IF(D39="DOSEN",VLOOKUP(B39,Dosen!B:ZZ,33,FALSE),VLOOKUP(B39,TPA!B:ZZ,44,FALSE)) -> S2 | N39: 45170 | P39: =IF(O39="",DATEDIF(N39,TODAY(),"y")&" tahun "&DATEDIF(N39,TODAY(),"ym")&" bulan ",DATEDIF(N39,O39,"y")&" tahun "&DATEDIF(N39,O39,"ym")&" bulan ") -> 2 tahun 4 bulan | Q39: arnimuarifah@ittelkom-sby.ac.id | R39: 85292632388 | S39: Mutiara Garden Blok A5, Sidoarjo, 61252
A40: 39 | B40: Amalia Nur Alifah | C40: Aktif | D40: Dosen | E40: =IF(D40="DOSEN",VLOOKUP(B40,Dosen!B:Z,11,FALSE),VLOOKUP(B40,TPA!B:Z,7,FALSE)) -> L | F40: Sains Data | G40: 20940044 | H40: 729129403 | I40: 1561772673230263 | J40: =IF(D40="DOSEN",VLOOKUP(B40,Dosen!B:Z,7,FALSE),VLOOKUP(B40,TPA!B:Z,5,FALSE)) -> TETAP | L40: S.Si., M.Si. | M40: =IF(D40="DOSEN",VLOOKUP(B40,Dosen!B:ZZ,33,FALSE),VLOOKUP(B40,TPA!B:ZZ,44,FALSE)) -> S2 | N40: 44166 | P40: =IF(O40="",DATEDIF(N40,TODAY(),"y")&" tahun "&DATEDIF(N40,TODAY(),"ym")&" bulan ",DATEDIF(N40,O40,"y")&" tahun "&DATEDIF(N40,O40,"ym")&" bulan ") -> 5 tahun 1 bulan | Q40: amalialifah@ittelkom-sby.ac.id | R40: 82229313437 | S40: Jl. Gondangmanis, Gondangmanis, BAE, Kudus
...

Sheet Sheet4
A3: Nama | B3: Program Studi | C3: Pendidikan | D3: Bidang Ilmu
A4: Dr. Mohammad Yanuar Hariyawan, S.T., M.T. | B4: S1 Teknik Telekomunikasi | C4: S1 Teknik Elektro - Telekomunikasi Multimedia S2 Teknik Elektro - Telekomunikasi Multimedia S3 Ilmu Teknik Elektro | D4: Electromagnetic Compatibility
A5: Dr. Helmy Widyantara, S.Kom, M.Eng. | B5: S1 Teknologi Informasi | C5: S1 Teknik Komputer S2 Teknik Elektro S3 Teknik Elektro | D5: Otomasi Sistem

Sheet Proyeksi LK GB
A1: No | B1: NAMA | C1: PRODI | D1: JAFA LLDIKTI | E1: TMT JAFA | F1: MASA JAFA | G1: Target
A2: =A1+1 -> #VALUE! | B2: Titus Kristanto | C2: Digital Bisnis | D2: L | E2: 44428 | F2: =DATEDIF(E2,TODAY(), "Y") & " Tahun " & DATEDIF(E2, TODAY(), "YM") & " Bulan" -> 4 Tahun 4 Bulan | G2: 2029
A3: =A2+1 -> #VALUE! | B3: Bambang Agus Sumantri | C3: Digital Bisnis | D3: L | E3: 44090 | F3: =DATEDIF(E3,TODAY(), "Y") & " Tahun " & DATEDIF(E3, TODAY(), "YM") & " Bulan" -> 5 Tahun 4 Bulan | G3: 2026
A4: =A3+1 -> #VALUE! | B4: Ahmad Wali Satria Bahari Johan | C4: Informatika | D4: L | E4: 45901 | F4: =DATEDIF(E4,TODAY(), "Y") & " Tahun " & DATEDIF(E4, TODAY(), "YM") & " Bulan" -> 0 Tahun 4 Bulan | G4: 2033
A5: =A4+1 -> #VALUE! | B5: Dyah Putri Rahmawati | C5: Informatika | D5: L | E5: 45870 | F5: =DATEDIF(E5,TODAY(), "Y") & " Tahun " & DATEDIF(E5, TODAY(), "YM") & " Bulan" -> 0 Tahun 5 Bulan | G5: =YEAR(E5)+5 -> 2030
A6: =A5+1 -> #VALUE! | B6: Fidi Wincoko Putro | C6: Rekayasa Perangkat Lunak | D6: L | E6: 45901 | F6: =DATEDIF(E6,TODAY(), "Y") & " Tahun " & DATEDIF(E6, TODAY(), "YM") & " Bulan" -> 0 Tahun 4 Bulan | G6: 2033
A7: =A6+1 -> #VALUE! | B7: Dewi Rahmawati | C7: Rekayasa Perangkat Lunak | D7: L | E7: 45108 | F7: =DATEDIF(E7,TODAY(), "Y") & " Tahun " & DATEDIF(E7, TODAY(), "YM") & " Bulan" -> 2 Tahun 6 Bulan | G7: =YEAR(E7)+5 -> 2028
A8: =A7+1 -> #VALUE! | B8: Achmad Muzakki | C8: Rekayasa Perangkat Lunak | D8: L | E8: 45901 | F8: =DATEDIF(E8,TODAY(), "Y") & " Tahun " & DATEDIF(E8, TODAY(), "YM") & " Bulan" -> 0 Tahun 4 Bulan | G8: 2033
A9: =A8+1 -> #VALUE! | B9: Dahliar Ananda | C9: Rekayasa Perangkat Lunak | D9: L | E9: 45627 | F9: =DATEDIF(E9,TODAY(), "Y") & " Tahun " & DATEDIF(E9, TODAY(), "YM") & " Bulan" -> 1 Tahun 1 Bulan | G9: 2033
A10: =A9+1 -> #VALUE! | B10: Alon Jala Tirta Segara | C10: Rekayasa Perangkat Lunak | D10: L | E10: 45261 | F10: =DATEDIF(E10,TODAY(), "Y") & " Tahun " & DATEDIF(E10, TODAY(), "YM") & " Bulan" -> 2 Tahun 1 Bulan | G10: =YEAR(E10)+5 -> 2028
A11: =A10+1 -> #VALUE! | B11: Moh. Hamim Zajuli Al Faroby | C11: Sains Data | D11: L | E11: 45931 | F11: =DATEDIF(E11,TODAY(), "Y") & " Tahun " & DATEDIF(E11, TODAY(), "YM") & " Bulan" -> 0 Tahun 3 Bulan | G11: 2033
A12: =A11+1 -> #VALUE! | B12: Noerma Pudji Istyanto | C12: Sistem Informasi | D12: L | E12: 45108 | F12: =DATEDIF(E12,TODAY(), "Y") & " Tahun " & DATEDIF(E12, TODAY(), "YM") & " Bulan" -> 2 Tahun 6 Bulan | G12: 2033
A13: =A12+1 -> #VALUE! | B13: Agus Sulistya | C13: Sistem Informasi | D13: L | E13: 45444 | F13: =DATEDIF(E13,TODAY(), "Y") & " Tahun " & DATEDIF(E13, TODAY(), "YM") & " Bulan" -> 1 Tahun 7 Bulan | G13: 2033
A14: =A13+1 -> #VALUE! | B14: Dimas Adiputra | C14: Teknik Elektro | D14: L | E14: 45108 | F14: =DATEDIF(E14,TODAY(), "Y") & " Tahun " & DATEDIF(E14, TODAY(), "YM") & " Bulan" -> 2 Tahun 6 Bulan | G14: 2027
A15: =A14+1 -> #VALUE! | B15: Isa Hafidz | C15: Teknik Elektro | D15: L | E15: 45108 | F15: =DATEDIF(E15,TODAY(), "Y") & " Tahun " & DATEDIF(E15, TODAY(), "YM") & " Bulan" -> 2 Tahun 6 Bulan | G15: =YEAR(E15)+5 -> 2028
A16: =A15+1 -> #VALUE! | B16: Lora Khaula Amifia | C16: Teknik Elektro | D16: L | E16: 44805 | F16: =DATEDIF(E16,TODAY(), "Y") & " Tahun " & DATEDIF(E16, TODAY(), "YM") & " Bulan" -> 3 Tahun 4 Bulan | G16: 2033
A17: =A16+1 -> #VALUE! | B17: Chaironi Latif | C17: Teknik Elektro | D17: L | E17: 45962 | F17: =DATEDIF(E17,TODAY(), "Y") & " Tahun " & DATEDIF(E17, TODAY(), "YM") & " Bulan" -> 0 Tahun 2 Bulan | G17: 2033
A18: =A17+1 -> #VALUE! | B18: Wahyu Andy Prastyabudi | C18: Teknik Industri | D18: L | E18: 45108 | F18: =DATEDIF(E18,TODAY(), "Y") & " Tahun " & DATEDIF(E18, TODAY(), "YM") & " Bulan" -> 2 Tahun 6 Bulan | G18: 2030
A19: =A18+1 -> #VALUE! | B19: Rizqa Amelia Zunaidi | C19: Teknik Industri | D19: L | E19: 44927 | F19: =DATEDIF(E19,TODAY(), "Y") & " Tahun " & DATEDIF(E19, TODAY(), "YM") & " Bulan" -> 3 Tahun 0 Bulan | G19: 2033
A20: =A19+1 -> #VALUE! | B20: Benazir Imam Arif Muttaqin | C20: Teknik Industri | D20: L | E20: 44866 | F20: =DATEDIF(E20,TODAY(), "Y") & " Tahun " & DATEDIF(E20, TODAY(), "YM") & " Bulan" -> 3 Tahun 2 Bulan | G20: =YEAR(E20)+5 -> 2027
A21: =A20+1 -> #VALUE! | B21: Ayu Endah Wahyuni | C21: Teknik Industri | D21: L | E21: 45108 | F21: =DATEDIF(E21,TODAY(), "Y") & " Tahun " & DATEDIF(E21, TODAY(), "YM") & " Bulan" -> 2 Tahun 6 Bulan | G21: 2033
A22: =A21+1 -> #VALUE! | B22: Ubaidillah Umar | C22: Teknik Komputer | D22: L | E22: 45413 | F22: =DATEDIF(E22,TODAY(), "Y") & " Tahun " & DATEDIF(E22, TODAY(), "YM") & " Bulan" -> 1 Tahun 8 Bulan | G22: 2030
A23: =A22+1 -> #VALUE! | B23: Ardiansyah Al Farouq | C23: Teknik Komputer | D23: L | E23: 44805 | F23: =DATEDIF(E23,TODAY(), "Y") & " Tahun " & DATEDIF(E23, TODAY(), "YM") & " Bulan" -> 3 Tahun 4 Bulan | G23: 2031
A24: =A23+1 -> #VALUE! | B24: Susijanto Tri Rasmana | C24: Teknik Komputer | D24: L | E24: 45108 | F24: =DATEDIF(E24,TODAY(), "Y") & " Tahun " & DATEDIF(E24, TODAY(), "YM") & " Bulan" -> 2 Tahun 6 Bulan | G24: =YEAR(E24)+5 -> 2028
A25: =A24+1 -> #VALUE! | B25: Abduh Sayid Albana | C25: Teknik Logistik | D25: L | E25: 44032 | F25: =DATEDIF(E25,TODAY(), "Y") & " Tahun " & DATEDIF(E25, TODAY(), "YM") & " Bulan" -> 5 Tahun 5 Bulan | G25: 2027
A26: =A25+1 -> #VALUE! | B26: Erly Ekayanti Rosyida | C26: Teknik Logistik | D26: L | E26: 41365 | F26: =DATEDIF(E26,TODAY(), "Y") & " Tahun " & DATEDIF(E26, TODAY(), "YM") & " Bulan" -> 12 Tahun 9 Bulan | G26: 2027
A27: =A26+1 -> #VALUE! | B27: Muhsin | C27: Teknik Telekomunikasi | D27: L | E27: 45108 | F27: =DATEDIF(E27,TODAY(), "Y") & " Tahun " & DATEDIF(E27, TODAY(), "YM") & " Bulan" -> 2 Tahun 6 Bulan | G27: =YEAR(E27)+5 -> 2028
A28: =A27+1 -> #VALUE! | B28: Fannush Shofi Akbar | C28: Teknik Telekomunikasi | D28: L | E28: 45108 | F28: =DATEDIF(E28,TODAY(), "Y") & " Tahun " & DATEDIF(E28, TODAY(), "YM") & " Bulan" -> 2 Tahun 6 Bulan | G28: =YEAR(E28)+5 -> 2028
A29: =A28+1 -> #VALUE! | B29: Hendy Briantoro | C29: Teknik Telekomunikasi | D29: L | E29: 45597 | F29: =DATEDIF(E29,TODAY(), "Y") & " Tahun " & DATEDIF(E29, TODAY(), "YM") & " Bulan" -> 1 Tahun 2 Bulan | G29: 2033
A30: 1 | B30: Mohammad Yanuar Hariyawan | C30: Teknik Telekomunikasi | D30: LK | E30: 41852 | F30: =DATEDIF(E30,TODAY(), "Y") & " Tahun " & DATEDIF(E30, TODAY(), "YM") & " Bulan" -> 11 Tahun 5 Bulan | G30: 2027
A31: =A30+1 -> 2 | B31: Khodijah Amiroh | C31: Teknologi Informasi | D31: L | E31: 44958 | F31: =DATEDIF(E31,TODAY(), "Y") & " Tahun " & DATEDIF(E31, TODAY(), "YM") & " Bulan" -> 2 Tahun 11 Bulan | G31: 2029
A32: =A31+1 -> 3 | B32: Farah Zakiyah Rahmanti | C32: Teknologi Informasi | D32: L | E32: 43984 | F32: =DATEDIF(E32,TODAY(), "Y") & " Tahun " & DATEDIF(E32, TODAY(), "YM") & " Bulan" -> 5 Tahun 7 Bulan | G32: 2029
A33: =A32+1 -> 4 | B33: Helmy Widyantara | C33: Teknologi Informasi | D33: LK | E33: 45200 | F33: =DATEDIF(E33,TODAY(), "Y") & " Tahun " & DATEDIF(E33, TODAY(), "YM") & " Bulan" -> 2 Tahun 3 Bulan | G33: 2028
A34: =A33+1 -> 5 | B34: Philip Tobianto Daely | C34: Teknologi Informasi | D34: L | E34: 45597 | F34: =DATEDIF(E34,TODAY(), "Y") & " Tahun " & DATEDIF(E34, TODAY(), "YM") & " Bulan" -> 1 Tahun 2 Bulan | G34: =YEAR(E34)+5 -> 2029
A35: =A34+1 -> 6 | B35: Bernadus Anggo Seno Aji | C35: Teknologi Informasi | D35: L | E35: 45931 | F35: =DATEDIF(E35,TODAY(), "Y") & " Tahun " & DATEDIF(E35, TODAY(), "YM") & " Bulan" -> 0 Tahun 3 Bulan | G35: 2033

Sheet Dosen
A1: No | B1: NAMA | C1: Status Aktif | D1: PRODI | E1: NIP YPT | F1: NIDN | G1: NUPTK | H1: STATUS | I1: GELAR DEPAN | J1: GELAR BELAKANG | K1: ENTRY LEVEL | L1: JAFA LLDIKTI | M1: KENAIKAN JAFA KE- | N1: PROGRESS JAFUNG | O1: KUM JAFA TERAKHIR LLDIKTI | P1: BIDANG KEILMUAN JAFA TERAKHIR LLDIKTI | Q1: TMT JAFA TERAKHIR LLDIKTI / TMT DOSEN TETAP | R1: MASA JAFA TERAKHIR LLDIKTI (TAHUN) | S1: PANGKAT / GOLONGAN TERAKHIR | T1: TMT PANGKAT | U1: MASA KERJA PANGKAT TERAKHIR LLDIKTI | V1: POSISI | W1: PROFESI | X1: Nominasi Serdos | Y1: Eligible / Progress Serdos | Z1: SERTIFIKASI DOSEN | AA1: NOMOR REGISTRASI SERDOS | AB1: NOMOR SK SERDOS | AC1: TANGGAL SERDOS | AD1: NIRA | AE1: NOMOR NIRA | AF1: NOMOR SK NIRA | AG1: TANGGAL NIRA | AH1: PENDIDIKAN TERAKHIR | AI1: On Progress S3 | AJ1: JENIS IZIN STUDI | AK1: PID | AL1: PROGRESS PENDIDIKAN | AM1: TMT MASUK DOSEN (SESUAI KONTRAK) | AN1: MASA KERJA DOSEN | AO1: FAKULTAS | AP1: LOKASI KERJA PRODI FAKULTAS | AQ1: KODE DOSEN | AR1: Email Domain | AS1: No HP | AT1: ALAMAT | AU1: Keterangan Pindah Homebase / NIDN | AW1: Nama Gelar | AX1: Jenis Kelamin | AY1: Tempat Lahir | AZ1: Tanggal Lahir | BA1: Usia | BB1: Tahun dari TMT | BC1: Batas Eligibilitas | BD1: Tahun dari TMT | BE1: Eligible naik pangkat? | BF1: JENIS PEMBIAYAAN S3 | BG1: KATEGORI BEASISWA | BH1: NO. PID | BI1: TANGGAL PID | BJ1: TANGGAL MULAI PID | BK1: TANGGAL SELESAI PID | BL1: Struktural | BM1: TMT Non Aktif | BN1: TMT S3 | BO1: Selisih S3 | BP1: Selisih S3 (sems) | BQ1: Kelompok Keahlian ITTS | BR1: Kelompok Keahlian Tel-U | BS1: Kode Dosen Baru | BT1: FAKULTAS TELKOM UNIVERSITY SURABAYA | BU1: Email Domain Telkom University | BW1: MASA KERJA 1 Januari 2026 | BX1: S1 Kampus | BY1: S1 Prodi | BZ1: S2 Kampus | CA1: S2 Prodi | CB1: S3 Kampus | CC1: S3 Prodi | CD1: COE | CE1: KK | CF1: TGL NON AKTIF
A2: 26 | B2: Dominggo Bayu Baskara | C2: Aktif | D2: Digital Bisnis | E2: 19900005 | F2: 0722069004 | G2: 6954768669130292 | H2: TETAP | I2: Ir. | J2: S.T., M.MT. | K2: AA.2 | L2: AA | M2: =IF(L2="NJAD","AA",IF(L2="AA","L",IF(L2="L","LK","GB"))) -> L | N2: - | O2: 150 | P2: Manajemen Proyek dan Studi Kelayakan | Q2: 43990 | R2: =DATEDIF(Q2,TODAY(), "Y") & " Tahun " & DATEDIF(Q2, TODAY(), "YM") & " Bulan" -> 5 Tahun 7 Bulan | S2: Penata Muda Tk. I Golongan III/b | T2: 44044 | U2: =DATEDIF(T2,TODAY(), "Y") & " Tahun " & DATEDIF(T2, TODAY(), "YM") & " Bulan" -> 5 Tahun 5 Bulan | V2: Dosen S1 Digital Bisnis | W2: DOSEN | X2: =IF(AND(OR(L2="AA",L2="L"),OR(S2="Penata Muda Tk. I Golongan III/b",S2="Penata Golongan III/c"),DATEDIF(Q2,TODAY(),"m")>=23,ISBLANK(Z2),C2="Aktif"),"Nominasi Serdos","-") -> - | Z2: Punya | AA2: 22107201905191 | AB2: 22-001027-0048 | AC2: 44846 | AH2: S2 | AI2: Ya | AJ2: TB | AK2: Ya | AL2: On Progress S3 TB | AM2: 43101 | AN2: =DATEDIF(AM2,TODAY(),"y")&" tahun "&DATEDIF(AM2,TODAY(),"ym")&" bulan " -> 8 tahun 0 bulan | AO2: FTIB | AP2: Program Studi S1 Digital Bisnis (FTIB) | AQ2: DMI | AR2: domi@ittelkom-sby.ac.id | AS2: 85230001444 | AT2: Jl. Palem Selatan II MC/163, Waru, Sidoarjo, Jawa Timur 61256 | AW2: =VLOOKUP(B2,Sheet2!A27:I144,9,FALSE) -> Dominggo Bayu Baskara, S.T., M.MT. | AX2: Laki-laki | AY2: =VLOOKUP(B2,Sheet2!A27:C144,2,FALSE) -> Denpasar | AZ2: =VLOOKUP(B2,Sheet2!A27:C144,3,FALSE) -> 33046 | BA2: =DATEDIF(AZ2, TODAY(),"y") -> 35 | BL2: =VLOOKUP(B2,Sheet2!A27:D144,4,FALSE) -> Dosen | BR2: =VLOOKUP(B2,Sheet2!A27:E144,5,FALSE) -> Strategy, Human, Entrepreneurship & Economy (SHEE) | BS2: =VLOOKUP(B2,Sheet2!A27:F144,6,FALSE) -> DBB | BT2: =VLOOKUP(B2,Sheet2!A27:G144,7,FALSE) -> Fakultas Ekonomi dan Bisnis | BU2: =VLOOKUP(B2,Sheet2!A27:H144,8,FALSE) -> dominggobayu@telkomuniversity.ac.id | BV2: =COUNTIFS('Join TPA Dosen'!B:B,Dosen!B23) -> 1 | BW2: =DATEDIF(AM2,DATE(2026,1,1),"y")&" tahun "&DATEDIF(AM2,DATE(2026,1,1),"ym")&" bulan " -> 8 tahun 0 bulan | BX2: =VLOOKUP($B2,Sheet1!$A:$G,2,FALSE) -> ITS | BY2: =VLOOKUP($B2,Sheet1!$A:$G,3,FALSE) -> Teknologi Industri/Teknik Industri | BZ2: =VLOOKUP($B2,Sheet1!$A:$G,4,FALSE) -> ITS | CA2: =VLOOKUP($B2,Sheet1!$A:$G,5,FALSE) -> Manajemen Teknologi | CB2: =VLOOKUP($B2,Sheet1!$A:$G,6,FALSE) -> ITS | CC2: =VLOOKUP($B2,Sheet1!$A:$G,7,FALSE) -> Manajemen Teknologi | CD2: Intergrated and Embedded Systems | CE2: Rekayasa Industri dan Inovasi Bisnis (RIIB)
A3: 1 | B3: Tri Agus Djoko Kuntjoro | C3: Aktif | D3: Teknik Telekomunikasi | E3: 25620001 | F3: 0728016901 | G3: 0460740641130052 | H3: TETAP | I3: Ir. | J3: M.T. | K3: AA.2 | L3: AA | M3: =IF(L3="NJAD","AA",IF(L3="AA","L",IF(L3="L","LK","GB"))) -> L | N3: - | O3: 150 | P3: Konsep Pengembangan Sains dan Teknologi Telekomunikasi dan Pengenalan Teknik Telekomunikasi | Q3: 44144 | R3: =DATEDIF(Q3,TODAY(), "Y") & " Tahun " & DATEDIF(Q3, TODAY(), "YM") & " Bulan" -> 5 Tahun 2 Bulan | S3: Penata Muda Tk. I Golongan III/b | T3: 44256 | U3: =DATEDIF(T3,TODAY(), "Y") & " Tahun " & DATEDIF(T3, TODAY(), "YM") & " Bulan" -> 4 Tahun 10 Bulan | V3: Dosen S1 T. Telekomunikasi | W3: DOSEN | X3: =IF(AND(OR(L3="AA",L3="L"),OR(S3="Penata Muda Tk. I Golongan III/b",S3="Penata Golongan III/c"),DATEDIF(Q3,TODAY(),"m")>=23,ISBLANK(Z3),C3="Aktif"),"Nominasi Serdos","-") -> - | Z3: Punya | AA3: 25104105710770 | AB3: 25-002001-0035 | AC3: 45917 | AH3: S2 | AM3: 43101 | AN3: =DATEDIF(AM3,TODAY(),"y")&" tahun "&DATEDIF(AM3,TODAY(),"ym")&" bulan " -> 8 tahun 0 bulan | AO3: FTEIC | AP3: Program Studi S1 T. Telekomunikasi (FTEIC) | AQ3: TRI | AR3: triagus@ittelkom-sby.ac.id | AS3: 8123222469 | AT3: Jl. Danau sentani Utara H2A No. 31, Sawojajar, Malang | AW3: =VLOOKUP(B3,Sheet2!A2:I119,9,FALSE) -> Ir. Tri Agus Djoko Kuntjoro, M.T. | AX3: Laki-laki | AY3: =VLOOKUP(B3,Sheet2!A2:C119,2,FALSE) -> Malang | AZ3: =VLOOKUP(B3,Sheet2!A2:C119,3,FALSE) -> 22674 | BA3: =DATEDIF(AZ3, TODAY(),"y") -> 63 | BL3: =VLOOKUP(B3,Sheet2!A2:D119,4,FALSE) -> Dosen | BR3: =VLOOKUP(B3,Sheet2!A2:E119,5,FALSE) -> Intelligent Communications and Networks (ICON) | BS3: =VLOOKUP(B3,Sheet2!A2:F119,6,FALSE) -> ORO | BT3: =VLOOKUP(B3,Sheet2!A2:G119,7,FALSE) -> Fakultas Teknik Elektro | BU3: =VLOOKUP(B3,Sheet2!A2:H119,8,FALSE) -> triagusdjokokuntjoro@telkomuniversity.ac.id | BV3: =COUNTIFS('Join TPA Dosen'!B:B,Dosen!B2) -> 1 | BW3: =DATEDIF(AM3,DATE(2026,1,1),"y")&" tahun "&DATEDIF(AM3,DATE(2026,1,1),"ym")&" bulan " -> 8 tahun 0 bulan | BX3: =VLOOKUP($B3,Sheet1!$A:$G,2,FALSE) -> Univ. Brawijaya | BY3: =VLOOKUP($B3,Sheet1!$A:$G,3,FALSE) -> Teknik Elektro | BZ3: =VLOOKUP($B3,Sheet1!$A:$G,4,FALSE) -> ITB | CA3: =VLOOKUP($B3,Sheet1!$A:$G,5,FALSE) -> Elektroteknik | CB3: =VLOOKUP($B3,Sheet1!$A:$G,6,FALSE) -> - | CC3: =VLOOKUP($B3,Sheet1!$A:$G,7,FALSE) -> 0 | CD3: Circular Ecosystem and Sustainable Technology | CE3: ETHES (Electrical Engineering and Advanced Technologies)
A4: 5 | B4: Dimas Adiputra | C4: Aktif | D4: Teknik Elektro | E4: 19930001 | F4: 0725059301 | G4: 2857771672130342 | H4: TETAP | J4: B.Sc., M.Phil., Ph.D. | K4: L.3 | L4: L | M4: =IF(L4="NJAD","AA",IF(L4="AA","L",IF(L4="L","LK","GB"))) -> LK | O4: 300 | P4: Sistem Kendali, Pratikum Sistem Kendali, Elektronika dan Literasi TIK | Q4: 45108 | R4: =DATEDIF(Q4,TODAY(), "Y") & " Tahun " & DATEDIF(Q4, TODAY(), "YM") & " Bulan" -> 2 Tahun 6 Bulan | S4: Penata Golongan III/c | T4: 45261 | U4: =DATEDIF(T4,TODAY(), "Y") & " Tahun " & DATEDIF(T4, TODAY(), "YM") & " Bulan" -> 2 Tahun 1 Bulan | V4: Ketua Kelompok Riset Motion Analysis And Intervention | W4: DOSEN | X4: =IF(AND(OR(L4="AA",L4="L"),OR(S4="Penata Muda Tk. I Golongan III/b",S4="Penata Golongan III/c"),DATEDIF(Q4,TODAY(),"m")>=23,ISBLANK(Z4),C4="Aktif"),"Nominasi Serdos","-") -> - | Z4: Punya | AA4: 22107201901078 | AB4: 22-001001-0182 | AC4: 44783 | AH4: S3 | AM4: 43101 | AN4: =DATEDIF(AM4,TODAY(),"y")&" tahun "&DATEDIF(AM4,TODAY(),"ym")&" bulan " -> 8 tahun 0 bulan | AO4: FTEIC | AP4: Program Studi S1 Teknik Elektro (FTEIC) | AQ4: DMS | AR4: adimas@ittelkom-sby.ac.id | AS4: 81335397727 | AT4: Jl. KH. Hasyim No. 35 RT009/RW002 Siwalanpanji Buduran Sidoarjo | AW4: =VLOOKUP(B4,Sheet2!A6:I123,9,FALSE) -> Dimas Adiputra, B.Sc., M.Phil., Ph.D. | AX4: Laki-laki | AY4: =VLOOKUP(B4,Sheet2!A6:C123,2,FALSE) -> Jakarta | AZ4: =VLOOKUP(B4,Sheet2!A6:C123,3,FALSE) -> 34114 | BA4: =DATEDIF(AZ4, TODAY(),"y") -> 32 | BL4: =VLOOKUP(B4,Sheet2!A6:D123,4,FALSE) -> COE | BR4: =VLOOKUP(B4,Sheet2!A6:E123,5,FALSE) -> Control, Elektronics, and Intelligent Systems (CEIS) | BS4: =VLOOKUP(B4,Sheet2!A6:F123,6,FALSE) -> DIV | BT4: =VLOOKUP(B4,Sheet2!A6:G123,7,FALSE) -> Fakultas Teknik Elektro | BU4: =VLOOKUP(B4,Sheet2!A6:H123,8,FALSE) -> dimasze@telkomuniversity.ac.id | BV4: =COUNTIFS('Join TPA Dosen'!B:B,Dosen!B22) -> 1 | BW4: =DATEDIF(AM4,DATE(2026,1,1),"y")&" tahun "&DATEDIF(AM4,DATE(2026,1,1),"ym")&" bulan " -> 8 tahun 0 bulan | BX4: =VLOOKUP($B4,Sheet1!$A:$G,2,FALSE) -> President Univ | BY4: =VLOOKUP($B4,Sheet1!$A:$G,3,FALSE) -> Teknik Elektro | BZ4: =VLOOKUP($B4,Sheet1!$A:$G,4,FALSE) -> Universiti Teknologi Malaysia | CA4: =VLOOKUP($B4,Sheet1!$A:$G,5,FALSE) -> Teknik Elektro | CB4: =VLOOKUP($B4,Sheet1!$A:$G,6,FALSE) -> Universiti Teknologi Malaysia | CC4: =VLOOKUP($B4,Sheet1!$A:$G,7,FALSE) -> Teknik Elektro | CD4: Motion Technology for Safety, Health, and Wellness | CE4: ETHES (Electrical Engineering and Advanced Technologies)
A5: 47 | B5: Riza Akhsani Setyo Prayoga | C5: Non-Aktif | D5: Digital Bisnis | E5: 20940041 | F5: 0730049402 | H5: PROFESIONAL | J5: S.Kom., M.MT. | K5: AA.2 | L5: AA | M5: =IF(L5="NJAD","AA",IF(L5="AA","L",IF(L5="L","LK","GB"))) -> L | N5: - | O5: 150 | P5: Pemodelan Proses Bisnis, Literasi TIK dan Pemodelan Bisnis | Q5: 44805 | R5: =DATEDIF(Q5,TODAY(), "Y") & " Tahun " & DATEDIF(Q5, TODAY(), "YM") & " Bulan" -> 3 Tahun 4 Bulan | S5: Penata Muda Tk. I Golongan III/b | T5: 44927 | U5: =DATEDIF(T5,TODAY(), "Y") & " Tahun " & DATEDIF(T5, TODAY(), "YM") & " Bulan" -> 3 Tahun 0 Bulan | V5: Dosen S1 Digital Bisnis | W5: DOSEN | X5: =IF(AND(OR(L5="AA",L5="L"),OR(S5="Penata Muda Tk. I Golongan III/b",S5="Penata Golongan III/c"),DATEDIF(Q5,TODAY(),"m")>=23,ISBLANK(Z5),C5="Aktif"),"Nominasi Serdos","-") -> - | AC5: - | AH5: S2 | AM5: 44166 | AN5: =DATEDIF(AM5,TODAY(),"y")&" tahun "&DATEDIF(AM5,TODAY(),"ym")&" bulan " -> 5 tahun 1 bulan | AO5: FTIB | AP5: Program Studi S1 Digital Bisnis (FTIB) | AQ5: RAS | AR5: rizayoga30@ittelkom-sby.ac.id | AS5: 81286153175 | AT5: Jl. Ukel GG 1 No. 26, Kertosari, Babadan, Ponorogo | AW5: =VLOOKUP(B5,Sheet2!A48:I165,9,FALSE) -> Riza Akhsani Setyo Prayoga, S.Kom., M.MT. | AX5: Laki-laki | AY5: =VLOOKUP(B5,Sheet2!A48:C165,2,FALSE) -> Ponorogo | AZ5: =VLOOKUP(B5,Sheet2!A48:C165,3,FALSE) -> 34454 | BA5: =DATEDIF(AZ5, TODAY(),"y") -> 31 | BL5: =VLOOKUP(B5,Sheet2!A48:D165,4,FALSE) -> Dosen | BR5: =VLOOKUP(B5,Sheet2!A48:E165,5,FALSE) -> ICT Business Management (IBM) | BS5: =VLOOKUP(B5,Sheet2!A48:F165,6,FALSE) -> OGA | BT5: =VLOOKUP(B5,Sheet2!A48:G165,7,FALSE) -> Fakultas Ekonomi dan Bisnis | BU5: =VLOOKUP(B5,Sheet2!A48:H165,8,FALSE) -> rizayoga@telkomuniversity.ac.id | BV5: =COUNTIFS('Join TPA Dosen'!B:B,Dosen!B48) -> 1 | BW5: =DATEDIF(AM5,DATE(2026,1,1),"y")&" tahun "&DATEDIF(AM5,DATE(2026,1,1),"ym")&" bulan " -> 5 tahun 1 bulan | BX5: =VLOOKUP($B5,Sheet1!$A:$G,2,FALSE) -> Univ. Brawijaya | BY5: =VLOOKUP($B5,Sheet1!$A:$G,3,FALSE) -> Ilmu Komputer/Sistem Informasi | BZ5: =VLOOKUP($B5,Sheet1!$A:$G,4,FALSE) -> ITS | CA5: =VLOOKUP($B5,Sheet1!$A:$G,5,FALSE) -> Bisnis dan Manajemen Teknologi/Manajemen Teknologi | CB5: =VLOOKUP($B5,Sheet1!$A:$G,6,FALSE) -> - | CC5: =VLOOKUP($B5,Sheet1!$A:$G,7,FALSE) -> 0 | CD5: #N/A | CE5: #N/A
A6: 6 | B6: Isa Hafidz | C6: Aktif | D6: Teknik Elektro | E6: 19920002 | F6: 0728059203 | G6: 5860770671130292 | H6: TETAP | I6: Dr. | J6: S.T., M.T. | K6: L.3 | L6: L | M6: =IF(L6="NJAD","AA",IF(L6="AA","L",IF(L6="L","LK","GB"))) -> LK | O6: 200 | P6: Rangakaian Listrik, Praktikum Rangkaian Listrik, Elektromagnetika dan Matematika Teknik | Q6: 45108 | R6: =DATEDIF(Q6,TODAY(), "Y") & " Tahun " & DATEDIF(Q6, TODAY(), "YM") & " Bulan" -> 2 Tahun 6 Bulan | S6: Penata Golongan III/c | T6: 45658 | U6: =DATEDIF(T6,TODAY(), "Y") & " Tahun " & DATEDIF(T6, TODAY(), "YM") & " Bulan" -> 1 Tahun 0 Bulan | V6: Kaprodi S1 Teknik Elektro | W6: DOSEN | X6: =IF(AND(OR(L6="AA",L6="L"),OR(S6="Penata Muda Tk. I Golongan III/b",S6="Penata Golongan III/c"),DATEDIF(Q6,TODAY(),"m")>=23,ISBLANK(Z6),C6="Aktif"),"Nominasi Serdos","-") -> - | Z6: Punya | AA6: 22107201902507 | AB6: 22-002001-01238 | AC6: 44783 | AH6: S3 | AM6: 43101 | AN6: =DATEDIF(AM6,TODAY(),"y")&" tahun "&DATEDIF(AM6,TODAY(),"ym")&" bulan " -> 8 tahun 0 bulan | AO6: FTEIC | AP6: Program Studi S1 Teknik Elektro (FTEIC) | AQ6: ISA | AR6: isa@ittelkom-sby.ac.id | AS6: 85234852155 | AT6: Jl. Tambak Deres 6/2, Surabaya | AW6: =VLOOKUP(B6,Sheet2!A7:I124,9,FALSE) -> Dr. Isa Hafidz, S.T., M.T. | AX6: Laki-laki | AY6: =VLOOKUP(B6,Sheet2!A7:C124,2,FALSE) -> Surabaya | AZ6: =VLOOKUP(B6,Sheet2!A7:C124,3,FALSE) -> 33752 | BA6: =DATEDIF(AZ6, TODAY(),"y") -> 33 | BL6: =VLOOKUP(B6,Sheet2!A7:D124,4,FALSE) -> Kaprodi | BR6: =VLOOKUP(B6,Sheet2!A7:E124,5,FALSE) -> Control, Elektronics, and Intelligent Systems (CEIS) | BS6: =VLOOKUP(B6,Sheet2!A7:F124,6,FALSE) -> IHF | BT6: =VLOOKUP(B6,Sheet2!A7:G124,7,FALSE) -> Fakultas Teknik Elektro | BU6: =VLOOKUP(B6,Sheet2!A7:H124,8,FALSE) -> isahafidz@telkomuniversity.ac.id | BV6: =COUNTIFS('Join TPA Dosen'!B:B,Dosen!B31) -> 1 | BW6: =DATEDIF(AM6,DATE(2026,1,1),"y")&" tahun "&DATEDIF(AM6,DATE(2026,1,1),"ym")&" bulan " -> 8 tahun 0 bulan | BX6: =VLOOKUP($B6,Sheet1!$A:$G,2,FALSE) -> ITS | BY6: =VLOOKUP($B6,Sheet1!$A:$G,3,FALSE) -> Teknik Elektro | BZ6: =VLOOKUP($B6,Sheet1!$A:$G,4,FALSE) -> ITS | CA6: =VLOOKUP($B6,Sheet1!$A:$G,5,FALSE) -> Teknik Elektro - Teknik Sistem Tenaga | CB6: =VLOOKUP($B6,Sheet1!$A:$G,6,FALSE) -> ITS | CC6: =VLOOKUP($B6,Sheet1!$A:$G,7,FALSE) -> Teknik Elektro | CD6: Circular Ecosystem and Sustainable Technology | CE6: ETHES (Electrical Engineering and Advanced Technologies)
A7: 8 | B7: Farah Zakiyah Rahmanti | C7: Aktif | D7: Teknologi Informasi | E7: 20870006 | F7: 0715128708 | G7: 9547765666230283 | H7: TETAP | J7: S.ST., M.T. | K7: L.2 | L7: L | M7: =IF(L7="NJAD","AA",IF(L7="AA","L",IF(L7="L","LK","GB"))) -> LK | N7: - | O7: 200 | P7: Pemrograman Mobile, Praktikum Algoritma dan Pemrograman, Matermatika Diskrit, Perancangan Basis Data | Q7: 43984 | R7: =DATEDIF(Q7,TODAY(), "Y") & " Tahun " & DATEDIF(Q7, TODAY(), "YM") & " Bulan" -> 5 Tahun 7 Bulan | S7: Penata Golongan III/c | T7: 46023 | U7: =DATEDIF(T7,TODAY(), "Y") & " Tahun " & DATEDIF(T7, TODAY(), "YM") & " Bulan" -> 0 Tahun 0 Bulan | V7: Dosen S1 Teknologi Informasi | W7: DOSEN | X7: =IF(AND(OR(L7="AA",L7="L"),OR(S7="Penata Muda Tk. I Golongan III/b",S7="Penata Golongan III/c"),DATEDIF(Q7,TODAY(),"m")>=23,ISBLANK(Z7),C7="Aktif"),"Nominasi Serdos","-") -> - | Z7: Punya | AA7: 21107201900219 | AB7: 21-002002-0035 | AC7: 44529 | AH7: S2 | AI7: Ya | AJ7: IB | AK7: Tidak | AL7: On Progress S3 IB | AM7: 43101 | AN7: =DATEDIF(AM7,TODAY(),"y")&" tahun "&DATEDIF(AM7,TODAY(),"ym")&" bulan " -> 8 tahun 0 bulan | AO7: FTIB | AP7: Program Studi S1 Teknologi Informasi (FTIB) | AQ7: FRH | AR7: farah.zakiyah@ittelkom-sby.ac.id | AS7: 82257336595 | AT7: Jl. Kutisari Indah Selatan 6/9, Surabaya | AW7: =VLOOKUP(B7,Sheet2!A9:I126,9,FALSE) -> Farah Zakiyah Rahmanti, S.ST., M.T. | AX7: Perempuan | AY7: =VLOOKUP(B7,Sheet2!A9:C126,2,FALSE) -> Surabaya | AZ7: =VLOOKUP(B7,Sheet2!A9:C126,3,FALSE) -> 32126 | BA7: =DATEDIF(AZ7, TODAY(),"y") -> 38 | BL7: =VLOOKUP(B7,Sheet2!A9:D126,4,FALSE) -> Dosen | BR7: =VLOOKUP(B7,Sheet2!A9:E126,5,FALSE) -> Data Science and Intelligent Systems (DSIS) | BS7: =VLOOKUP(B7,Sheet2!A9:F126,6,FALSE) -> FZK | BT7: =VLOOKUP(B7,Sheet2!A9:G126,7,FALSE) -> Fakultas Informatika | BU7: =VLOOKUP(B7,Sheet2!A9:H126,8,FALSE) -> farahzakiyah@telkomuniversity.ac.id | BV7: =COUNTIFS('Join TPA Dosen'!B:B,Dosen!B26) -> 1 | BW7: =DATEDIF(AM7,DATE(2026,1,1),"y")&" tahun "&DATEDIF(AM7,DATE(2026,1,1),"ym")&" bulan " -> 8 tahun 0 bulan | BX7: =VLOOKUP($B7,Sheet1!$A:$G,2,FALSE) -> PENS | BY7: =VLOOKUP($B7,Sheet1!$A:$G,3,FALSE) -> Teknik Informatika | BZ7: =VLOOKUP($B7,Sheet1!$A:$G,4,FALSE) -> ITS | CA7: =VLOOKUP($B7,Sheet1!$A:$G,5,FALSE) -> Teknik Elektro | CB7: =VLOOKUP($B7,Sheet1!$A:$G,6,FALSE) -> ITS | CC7: =VLOOKUP($B7,Sheet1!$A:$G,7,FALSE) -> Teknik Elektro | CD7: Intergrated and Embedded Systems | CE7: Smart Computing Technology (SCOUT)
A8: 9 | B8: Helmy Widyantara | C8: Aktif | D8: Teknologi Informasi | E8: 19790001 | F8: 0717017902 | G8: 9449757658130112 | H8: TETAP | I8: Dr. | J8: S.Kom., M.Eng. | K8: LK.3 | L8: LK | M8: =IF(L8="NJAD","AA",IF(L8="AA","L",IF(L8="L","LK","GB"))) -> GB | N8: - | O8: 400 | P8: Otomasi Sistem | Q8: 45200 | R8: =DATEDIF(Q8,TODAY(), "Y") & " Tahun " & DATEDIF(Q8, TODAY(), "YM") & " Bulan" -> 2 Tahun 3 Bulan | S8: Penata Tk. I Golongan III/d | T8: 46023 | U8: =DATEDIF(T8,TODAY(), "Y") & " Tahun " & DATEDIF(T8, TODAY(), "YM") & " Bulan" -> 0 Tahun 0 Bulan | V8: Ketua Kelompok Riset Integrated And Embedded System | W8: DOSEN | X8: =IF(AND(OR(L8="AA",L8="L"),OR(S8="Penata Muda Tk. I Golongan III/b",S8="Penata Golongan III/c"),DATEDIF(Q8,TODAY(),"m")>=23,ISBLANK(Z8),C8="Aktif"),"Nominasi Serdos","-") -> - | Z8: Punya | AA8: 15107500409985 | AB8: 15 00201 0454 | AC8: 42357 | AH8: S3 | AM8: 43101 | AN8: =DATEDIF(AM8,TODAY(),"y")&" tahun "&DATEDIF(AM8,TODAY(),"ym")&" bulan " -> 8 tahun 0 bulan | AO8: FTIB | AP8: Program Studi S1 Teknologi Informasi (FTIB) | AQ8: HEL | AR8: helmywid@ittelkom-sby.ac.id | AS8: 8123182116 | AT8: Semampir Tengah IIA/26 Surabaya | AW8: =VLOOKUP(B8,Sheet2!A10:I127,9,FALSE) -> Dr. Helmy Widyantara, S.Kom., M.Eng. | AX8: Laki-laki | AY8: =VLOOKUP(B8,Sheet2!A10:C127,2,FALSE) -> Ngawi | AZ8: =VLOOKUP(B8,Sheet2!A10:C127,3,FALSE) -> 28872 | BA8: =DATEDIF(AZ8, TODAY(),"y") -> 47 | BL8: =VLOOKUP(B8,Sheet2!A10:D127,4,FALSE) -> COE | BR8: =VLOOKUP(B8,Sheet2!A10:E127,5,FALSE) -> Communication and Information Technology Infrastructure (CITI) | BS8: =VLOOKUP(B8,Sheet2!A10:F127,6,FALSE) -> CAP | BT8: =VLOOKUP(B8,Sheet2!A10:G127,7,FALSE) -> Fakultas Informatika | BU8: =VLOOKUP(B8,Sheet2!A10:H127,8,FALSE) -> helmywidyantara@telkomuniversity.ac.id | BV8: =COUNTIFS('Join TPA Dosen'!B:B,Dosen!B30) -> 1 | BW8: =DATEDIF(AM8,DATE(2026,1,1),"y")&" tahun "&DATEDIF(AM8,DATE(2026,1,1),"ym")&" bulan " -> 8 tahun 0 bulan | BX8: =VLOOKUP($B8,Sheet1!$A:$G,2,FALSE) -> STIKOM | BY8: =VLOOKUP($B8,Sheet1!$A:$G,3,FALSE) -> Teknik Komputer | BZ8: =VLOOKUP($B8,Sheet1!$A:$G,4,FALSE) -> UGM | CA8: =VLOOKUP($B8,Sheet1!$A:$G,5,FALSE) -> Teknik Elektro | CB8: =VLOOKUP($B8,Sheet1!$A:$G,6,FALSE) -> ITS | CC8: =VLOOKUP($B8,Sheet1!$A:$G,7,FALSE) -> Teknik Elektro | CD8: Intergrated and Embedded Systems | CE8: Smart Computing Technology (SCOUT)
A9: 11 | B9: Fidi Wincoko Putro | C9: Aktif | D9: Rekayasa Perangkat Lunak | E9: 19870004 | F9: 0730058702 | G9: 1862765666130262 | H9: TETAP | J9: S.ST., M.Kom. | K9: L.2 | L9: L | M9: =IF(L9="NJAD","AA",IF(L9="AA","L",IF(L9="L","LK","GB"))) -> LK | N9: - | O9: 200 | P9: Software Engineering | Q9: 45901 | R9: =DATEDIF(Q9,TODAY(), "Y") & " Tahun " & DATEDIF(Q9, TODAY(), "YM") & " Bulan" -> 0 Tahun 4 Bulan | S9: Penata Golongan III/c | T9: 46023 | U9: =DATEDIF(T9,TODAY(), "Y") & " Tahun " & DATEDIF(T9, TODAY(), "YM") & " Bulan" -> 0 Tahun 0 Bulan | V9: Kaprodi S1 RPL | W9: DOSEN | X9: =IF(AND(OR(L9="AA",L9="L"),OR(S9="Penata Muda Tk. I Golongan III/b",S9="Penata Golongan III/c"),DATEDIF(Q9,TODAY(),"m")>=23,ISBLANK(Z9),C9="Aktif"),"Nominasi Serdos","-") -> - | Z9: Punya | AA9: 25104105710334 | AB9: 25-001026-0131 | AC9: 45917 | AH9: S2 | AI9: Ya | AJ9: TB | AK9: Ya | AM9: 43101 | AN9: =DATEDIF(AM9,TODAY(),"y")&" tahun "&DATEDIF(AM9,TODAY(),"ym")&" bulan " -> 8 tahun 0 bulan | AO9: FTIB | AP9: Program Studi S1 RPL (FTIB) | AQ9: FWP | AR9: fidiwputro@ittelkom-sby.ac.id | AS9: 82143161793 | AT9: Jl. Cempaka 42, Kel Bangunsari, Kec Mejayan, Kab Madiun, Jawa Timur | AW9: =VLOOKUP(B9,Sheet2!A12:I129,9,FALSE) -> Fidi Wincoko Putro, S.ST., M.Kom. | AX9: Laki-laki | AY9: =VLOOKUP(B9,Sheet2!A12:C129,2,FALSE) -> Madiun | AZ9: =VLOOKUP(B9,Sheet2!A12:C129,3,FALSE) -> 31927 | BA9: =DATEDIF(AZ9, TODAY(),"y") -> 38 | BL9: Dosen | BR9: =VLOOKUP(B9,Sheet2!A12:E129,5,FALSE) -> Software Engineering and Algorithm (SEAL) | BS9: =VLOOKUP(B9,Sheet2!A12:F129,6,FALSE) -> FWP | BT9: =VLOOKUP(B9,Sheet2!A12:G129,7,FALSE) -> Fakultas Informatika | BU9: =VLOOKUP(B9,Sheet2!A12:H129,8,FALSE) -> fidiwputro@telkomuniversity.ac.id | BV9: =COUNTIFS('Join TPA Dosen'!B:B,Dosen!B12) -> 1 | BW9: =DATEDIF(AM9,DATE(2026,1,1),"y")&" tahun "&DATEDIF(AM9,DATE(2026,1,1),"ym")&" bulan " -> 8 tahun 0 bulan | BX9: =VLOOKUP($B9,Sheet1!$A:$G,2,FALSE) -> PENS | BY9: =VLOOKUP($B9,Sheet1!$A:$G,3,FALSE) -> Teknik Informatika | BZ9: =VLOOKUP($B9,Sheet1!$A:$G,4,FALSE) -> ITS | CA9: =VLOOKUP($B9,Sheet1!$A:$G,5,FALSE) -> Teknik Informatika | CB9: =VLOOKUP($B9,Sheet1!$A:$G,6,FALSE) -> - | CC9: =VLOOKUP($B9,Sheet1!$A:$G,7,FALSE) -> 0 | CD9: Motion Technology for Safety, Health, and Wellness | CE9: Smart Computing Technology (SCOUT)
